{
	"registryname": "waste",
	"localizedname": "Recycler",
	"modifiers": [
		{
            "x": 0,
            "y": 2,
            "z": 0,
            "elements": [
                "contenttweaker:upgrade_equalizer@0"
            ],
			"modifier": {
				"io": "output",
				"target": "modularmachinery:item",
				"operation": 1,
				"multiplier": 2.0
			}
        },
		{
            "x": 0,
            "y": 2,
            "z": 0,
            "elements": [
                "contenttweaker:upgrade_equalizer@0"
            ],
			"modifier": {
				"io": "input",
				"target": "modularmachinery:item",
				"operation": 1,
				"multiplier": 2.0
			}
        },
		{
            "x": 0,
            "y": 2,
            "z": 0,
            "elements": [
                "contenttweaker:upgrade_equalizer@0"
            ],
			"modifier": {
				"io": "input",
				"target": "modularmachinery:energy",
				"operation": 1,
				"multiplier": 1.25
			}
        },
		{
            "x": 0,
            "y": 2,
            "z": 0,
            "elements": [
                "contenttweaker:upgrade_chance@0"
            ],
			"modifier": {
				"io": "input",
				"target": "modularmachinery:item",
				"operation": 0,
				"multiplier": -0.33,
				"affectChance": true
			}
        },
		{
            "x": 0,
            "y": 2,
            "z": 0,
            "elements": [
                "contenttweaker:upgrade_speed@0"
            ],
			"modifier": {
				"io": "input",
				"target": "modularmachinery:duration",
				"operation": 1,
				"multiplier": 0.75
			}
        },
		{
            "x": 0,
            "y": 2,
            "z": 0,
            "elements": [
                "contenttweaker:upgrade_sun@0"
            ],
			"modifier": {
				"io": "input",
				"target": "modularmachinery:duration",
				"operation": 1,
				"multiplier": 0.2
			}
        },
		{
            "x": 0,
            "y": 2,
            "z": 0,
            "elements": [
                "contenttweaker:upgrade_sun@0"
            ],
			"modifier": {
				"io": "input",
				"target": "modularmachinery:energy",
				"operation": 1,
				"multiplier": 5
			}
        }
	],
    "parts": [
        {
            "x": -1,
            "y": 0,
            "z": 0,
            "elements": [
                "modularmachinery:blockinputbus@6"
            ]
        },
        {
            "x": -1,
            "y": 0,
            "z": 1,
            "elements": [
                "factorytech:bricks@3"
            ]
        },
        {
            "x": 0,
            "y": 2,
            "z": 2,
            "elements": [
                "thermalfoundation:glass_alloy@2"
            ]
        },
        {
            "x": 1,
            "y": 2,
            "z": 1,
            "elements": [
                "thermalfoundation:glass_alloy@2"
            ]
        },
        {
            "x": 0,
            "y": 0,
            "z": 1,
            "elements": [
                "factorytech:bricks@3"
            ]
        },
        {
            "x": 1,
            "y": 0,
            "z": 0,
            "elements": [
                "modularmachinery:blockinputbus@6"
            ]
        },
        {
            "x": -1,
            "y": 0,
            "z": 2,
            "elements": [
                "modularmachinery:blockinputbus@6"
            ]
        },
        {
            "x": 1,
            "y": 2,
            "z": 2,
            "elements": [
                "thermalfoundation:glass_alloy@2"
            ]
        },
        {
            "x": 1,
            "y": 0,
            "z": 1,
            "elements": [
                "factorytech:bricks@3"
            ]
        },
        {
            "x": 0,
            "y": 0,
            "z": 2,
            "elements": [
                "factorytech:bricks@3"
            ]
        },
        {
            "x": 1,
            "y": 0,
            "z": 2,
            "elements": [
                "modularmachinery:blockinputbus@6"
            ]
        },
        {
            "x": -1,
            "y": 3,
            "z": 0,
            "elements": [
                "factorytech:bricks@3"
            ]
        },
        {
            "x": 0,
            "y": 3,
            "z": 0,
            "elements": [
                "factorytech:bricks@3"
            ]
        },
        {
            "x": -1,
            "y": 3,
            "z": 1,
            "elements": [
                "factorytech:bricks@3"
            ]
        },
        {
            "x": 0,
            "y": 3,
            "z": 1,
            "elements": [
                "modularmachinery:blockoutputbus@6"
            ]
        },
        {
            "x": 1,
            "y": 3,
            "z": 0,
            "elements": [
                "factorytech:bricks@3"
            ]
        },
        {
            "x": -1,
            "y": 1,
            "z": 0,
            "elements": [
                "thermalfoundation:glass_alloy@2"
            ]
        },
        {
            "x": -1,
            "y": 3,
            "z": 2,
            "elements": [
                "factorytech:bricks@3"
            ]
        },
        {
            "x": 0,
            "y": 3,
            "z": 2,
            "elements": [
                "factorytech:bricks@3"
            ]
        },
        {
            "x": 1,
            "y": 3,
            "z": 1,
            "elements": [
                "factorytech:bricks@3"
            ]
        },
        {
            "x": 0,
            "y": 1,
            "z": 0,
            "elements": [
                "modularmachinery:blockenergyinputhatch@7"
            ]
        },
        {
            "x": -1,
            "y": 1,
            "z": 1,
            "elements": [
                "thermalfoundation:glass_alloy@2"
            ]
        },
        {
            "x": 1,
            "y": 3,
            "z": 2,
            "elements": [
                "factorytech:bricks@3"
            ]
        },
        {
            "x": 0,
            "y": 1,
            "z": 1,
            "elements": [
                "extendedcrafting:storage@0"
            ]
        },
        {
            "x": 1,
            "y": 1,
            "z": 0,
            "elements": [
                "thermalfoundation:glass_alloy@2"
            ]
        },
        {
            "x": -1,
            "y": 1,
            "z": 2,
            "elements": [
                "thermalfoundation:glass_alloy@2"
            ]
        },
        {
            "x": 0,
            "y": 1,
            "z": 2,
            "elements": [
                "thermalfoundation:glass_alloy@2"
            ]
        },
        {
            "x": 1,
            "y": 1,
            "z": 1,
            "elements": [
                "thermalfoundation:glass_alloy@2"
            ]
        },
        {
            "x": 1,
            "y": 1,
            "z": 2,
            "elements": [
                "thermalfoundation:glass_alloy@2"
            ]
        },
        {
            "x": -1,
            "y": 2,
            "z": 0,
            "elements": [
                "thermalfoundation:glass_alloy@2"
            ]
        },
        {
            "x": -1,
            "y": 2,
            "z": 1,
            "elements": [
                "thermalfoundation:glass_alloy@2"
            ]
        },
        {
            "x": 0,
            "y": 2,
            "z": 0,
            "elements": [
                "thermalfoundation:glass_alloy@2"
            ]
        },
        {
            "x": -1,
            "y": 2,
            "z": 2,
            "elements": [
                "thermalfoundation:glass_alloy@2"
            ]
        },
        {
            "x": 0,
            "y": 2,
            "z": 1,
            "elements": [
                "thermalexpansion:machine@0"
            ]
        },
        {
            "x": 1,
            "y": 2,
            "z": 0,
            "elements": [
                "thermalfoundation:glass_alloy@2"
            ]
        }
    ],
	"modifiers": [
		{
            "x": 1,
            "y": 3,
            "z": 2,
            "elements": [
                "contenttweaker:bricks_upgrade@0"
            ],
			"description": "Upgrade bricks to add up to 64% chance to\nnot consume ingredients.",
			"modifier": {
				"io": "input",
				"target": "modularmachinery:item",
				"operation": 0,
				"multiplier": 0.04,
				"affectChance": true
			}
        },
		{
            "x": -1,
            "y": 0,
            "z": 1,
            "elements": [
                "contenttweaker:bricks_upgrade@0"
            ],
			"modifier": {
				"io": "input",
				"target": "modularmachinery:item",
				"operation": 0,
				"multiplier": 0.04,
				"affectChance": true
			}
        },
		{
            "x": 0,
            "y": 0,
            "z": 1,
            "elements": [
                "contenttweaker:bricks_upgrade@0"
            ],
			"modifier": {
				"io": "input",
				"target": "modularmachinery:item",
				"operation": 0,
				"multiplier": 0.04,
				"affectChance": true
			}
        },
		{
            "x": 1,
            "y": 0,
            "z": 1,
            "elements": [
                "contenttweaker:bricks_upgrade@0"
            ],
			"modifier": {
				"io": "input",
				"target": "modularmachinery:item",
				"operation": 0,
				"multiplier": 0.04,
				"affectChance": true
			}
        },
		{
            "x": 0,
            "y": 0,
            "z": 2,
            "elements": [
                "contenttweaker:bricks_upgrade@0"
            ],
			"modifier": {
				"io": "input",
				"target": "modularmachinery:item",
				"operation": 0,
				"multiplier": 0.04,
				"affectChance": true
			}
        },
		{
            "x": -1,
            "y": 3,
            "z": 0,
            "elements": [
                "contenttweaker:bricks_upgrade@0"
            ],
			"modifier": {
				"io": "input",
				"target": "modularmachinery:item",
				"operation": 0,
				"multiplier": 0.04,
				"affectChance": true
			}
        },
        {
            "x": 0,
            "y": 3,
            "z": 0,
            "elements": [
                "contenttweaker:bricks_upgrade@0"
            ],
			"modifier": {
				"io": "input",
				"target": "modularmachinery:item",
				"operation": 0,
				"multiplier": 0.04,
				"affectChance": true
			}
        },
        {
            "x": -1,
            "y": 3,
            "z": 1,
            "elements": [
                "contenttweaker:bricks_upgrade@0"
            ],
			"modifier": {
				"io": "input",
				"target": "modularmachinery:item",
				"operation": 0,
				"multiplier": 0.04,
				"affectChance": true
			}
        },
		{
            "x": 1,
            "y": 3,
            "z": 0,
            "elements": [
                "contenttweaker:bricks_upgrade@0"
            ],
			"modifier": {
				"io": "input",
				"target": "modularmachinery:item",
				"operation": 0,
				"multiplier": 0.04,
				"affectChance": true
			}
        },
		{
            "x": -1,
            "y": 3,
            "z": 2,
            "elements": [
                "contenttweaker:bricks_upgrade@0"
            ],
			"modifier": {
				"io": "input",
				"target": "modularmachinery:item",
				"operation": 0,
				"multiplier": 0.04,
				"affectChance": true
			}
        },
        {
            "x": 0,
            "y": 3,
            "z": 2,
            "elements": [
                "contenttweaker:bricks_upgrade@0"
            ],
			"modifier": {
				"io": "input",
				"target": "modularmachinery:item",
				"operation": 0,
				"multiplier": 0.04,
				"affectChance": true
			}
        },
        {
            "x": 1,
            "y": 3,
            "z": 1,
            "elements": [
                "contenttweaker:bricks_upgrade@0"
            ],
			"modifier": {
				"io": "input",
				"target": "modularmachinery:item",
				"operation": 0,
				"multiplier": 0.04,
				"affectChance": true
			}
        },
		{
            "x": 1,
            "y": 3,
            "z": 2,
            "elements": [
                "contenttweaker:bricks_upgrade@0"
            ],
			"modifier": {
				"io": "input",
				"target": "modularmachinery:item",
				"operation": 0,
				"multiplier": 0.04,
				"affectChance": true
			}
        }
	]
}